Workbook

Sheet Customer Names
A1: Customer ID | B1: Last Name | C1: Title | D1: First name
A2: Id1 | B2: Hawks | C2: Ms. | D2: Kelly
A3: Id2 | B3: Lehner | C3: Mr. | D3: Matthew D
A4: Id3 | B4: Lu | C4: Mr. | D4: Phil
A5: Id4 | B5: Osborne | C5: Ms. | D5: Kelsey
A6: Id5 | B6: Kadala | C6: Ms. | D6: Kristyn
A7: Id6 | B7: Baker | C7: Mr. | D7: Russell B.
A8: Id7 | B8: Macpherson | C8: Mr. | D8: Scott
A9: Id8 | B9: Hallman | C9: Mr. | D9: Stephen
A10: Id9 | B10: Moran | C10: Mr. | D10: Patrick R.
A11: Id10 | B11: Benner | C11: Ms. | D11: Brooke N.
A12: Id11 | B12: Fierro Vargas | C12: Ms. | D12: Paola Andrea
... A2336: Id2335 | B2336: German | C2336: Mr. | D2336: Aaron K

Sheet Medical Examinations
A1: =IFERROR(__xludf.DUMMYFUNCTION("INDEX(QUERY('Medical Examinations'!H2:H2336, ""select H, count(H) where H <> '?' and H is not null group by H order by count(H) desc limit 1 label count(H) ''""), 1, 1)"),"No") -> No | B1: BMI | C1: HBA1C | D1: Heart Issues | E1: Any Transplants | F1: Cancer history | G1: NumberOfMajorSurgeries | H1: smoker | I1: Weight Status
A2: Id1 | B2: 47.41 | C2: 7.47 | D2: No | E2: No | F2: No | G2: 0 | H2: yes | I2: =IF(B2<18.5, "Underweight", IF(B2<25, "Normal Weight", IF(B2<30, "Overweight", "Obesity"))) -> Obesity
A3: Id2 | B3: 30.36 | C3: 5.77 | D3: No | E3: No | F3: No | G3: 0 | H3: yes | I3: =IF(B3<18.5, "Underweight", IF(B3<25, "Normal Weight", IF(B3<30, "Overweight", "Obesity"))) -> Obesity
A4: Id3 | B4: 34.485 | C4: 11.87 | D4: yes | E4: No | F4: No | G4: 2 | H4: yes | I4: =IF(B4<18.5, "Underweight", IF(B4<25, "Normal Weight", IF(B4<30, "Overweight", "Obesity"))) -> Obesity
A5: Id4 | B5: 38.095 | C5: 6.05 | D5: No | E5: No | F5: No | G5: 0 | H5: yes | I5: =IF(B5<18.5, "Underweight", IF(B5<25, "Normal Weight", IF(B5<30, "Overweight", "Obesity"))) -> Obesity
A6: Id5 | B6: 35.53 | C6: 5.45 | D6: No | E6: No | F6: No | G6: 0 | H6: yes | I6: =IF(B6<18.5, "Underweight", IF(B6<25, "Normal Weight", IF(B6<30, "Overweight", "Obesity"))) -> Obesity
A7: Id6 | B7: 32.8 | C7: 6.59 | D7: No | E7: No | F7: No | G7: 0 | H7: yes | I7: =IF(B7<18.5, "Underweight", IF(B7<25, "Normal Weight", IF(B7<30, "Overweight", "Obesity"))) -> Obesity
A8: Id7 | B8: 36.4 | C8: 6.07 | D8: No | E8: No | F8: No | G8: 0 | H8: yes | I8: =IF(B8<18.5, "Underweight", IF(B8<25, "Normal Weight", IF(B8<30, "Overweight", "Obesity"))) -> Obesity
A9: Id8 | B9: 36.96 | C9: 7.93 | D9: No | E9: No | F9: No | G9: 3 | H9: yes | I9: =IF(B9<18.5, "Underweight", IF(B9<25, "Normal Weight", IF(B9<30, "Overweight", "Obesity"))) -> Obesity
A10: Id9 | B10: 41.14 | C10: 9.58 | D10: yes | E10: No | F10: Yes | G10: 1 | H10: yes | I10: =IF(B10<18.5, "Underweight", IF(B10<25, "Normal Weight", IF(B10<30, "Overweight", "Obesity"))) -> Obesity
A11: Id10 | B11: 38.06 | C11: 10.79 | D11: No | E11: No | F11: No | G11: 0 | H11: yes | I11: =IF(B11<18.5, "Underweight", IF(B11<25, "Normal Weight", IF(B11<30, "Overweight", "Obesity"))) -> Obesity
A12: Id11 | B12: 37.7 | C12: 5.96 | D12: yes | E12: No | F12: No | G12: 2 | H12: yes | I12: =IF(B12<18.5, "Underweight", IF(B12<25, "Normal Weight", IF(B12<30, "Overweight", "Obesity"))) -> Obesity
A13: Id12 | B13: 42.13 | C13: 11.9 | D13: No | E13: No | F13: No | G13: 0 | H13: yes | I13: =IF(B13<18.5, "Underweight", IF(B13<25, "Normal Weight", IF(B13<30, "Overweight", "Obesity"))) -> Obesity
... A2336: Id2335 | B2336: 17.58 | C2336: 4.51 | D2336: No | E2336: No | F2336: No | G2336: 1 | H2336: No | I2336: =IF(B2336<18.5, "Underweight", IF(B2336<25, "Normal Weight", IF(B2336<30, "Overweight", "Obesity"))) -> Underweight

Sheet Hospitalisation Details
A1: Customer ID | B1: year | C1: month | D1: date | E1: Date of birth | F1: children | G1: charges | H1: Hospital tier | I1: City tier | J1: State ID | K1: Age | M1: Column | N1: Missing values
A2: Id2335 | B2: 1992 | C2: Jul | D2: 9 | E2: =TEXT(DATEVALUE(D2 & "-" & C2 & "-" & B2), "dd/mm/yy") -> 09/07/92 | F2: 0 | G2: 563.84 | H2: tier - 2 | I2: tier - 3 | J2: R1013 | K2: =IFERROR(DATEDIF(DATEVALUE(D2 & "-" & C2 & "-" & B2), DATE(2023, 6, 8), "Y"), "No Data") -> 30 | M2: Customer ID | N2: =COUNTIF(A2:A2344,"~?") -> 0
A3: Id2334 | B3: 1992 | C3: Nov | D3: 30 | E3: =TEXT(DATEVALUE(D3 & "-" & C3 & "-" & B3), "dd/mm/yy") -> 30/11/92 | F3: 0 | G3: 570.62 | H3: tier - 2 | I3: tier - 1 | J3: R1013 | K3: =IFERROR(DATEDIF(DATEVALUE(D3 & "-" & C3 & "-" & B3), DATE(2023, 6, 8), "Y"), "No Data") -> 30 | M3: year | N3: =COUNTIF(B3:B2345,"~?") -> 0
A4: Id2333 | B4: 1993 | C4: Jun | D4: 30 | E4: =TEXT(DATEVALUE(D4 & "-" & C4 & "-" & B4), "dd/mm/yy") -> 30/06/93 | F4: 0 | G4: 600 | H4: tier - 2 | I4: tier - 1 | J4: R1013 | K4: =IFERROR(DATEDIF(DATEVALUE(D4 & "-" & C4 & "-" & B4), DATE(2023, 6, 8), "Y"), "No Data") -> 29 | M4: month | N4: =COUNTIF(C3:C2345,"~?") -> 0
A5: Id2332 | B5: 1992 | C5: Sep | D5: 13 | E5: =TEXT(DATEVALUE(D5 & "-" & C5 & "-" & B5), "dd/mm/yy") -> 13/09/92 | F5: 0 | G5: 604.54 | H5: tier - 3 | I5: tier - 3 | J5: R1013 | K5: =IFERROR(DATEDIF(DATEVALUE(D5 & "-" & C5 & "-" & B5), DATE(2023, 6, 8), "Y"), "No Data") -> 30 | M5: date | N5: =COUNTIF(D3:D2345,"~?") -> 0
A6: Id2331 | B6: 1998 | C6: Jul | D6: 27 | E6: =TEXT(DATEVALUE(D6 & "-" & C6 & "-" & B6), "dd/mm/yy") -> 27/07/98 | F6: 0 | G6: 637.26 | H6: tier - 3 | I6: tier - 3 | J6: R1013 | K6: =IFERROR(DATEDIF(DATEVALUE(D6 & "-" & C6 & "-" & B6), DATE(2023, 6, 8), "Y"), "No Data") -> 24 | M6: children | N6: =COUNTIF(F3:F2345,"~?") -> 0
A7: Id2330 | B7: 2001 | C7: Nov | D7: 20 | E7: =TEXT(DATEVALUE(D7 & "-" & C7 & "-" & B7), "dd/mm/yy") -> 20/11/01 | F7: 0 | G7: 646.14 | H7: tier - 3 | I7: tier - 3 | J7: R1012 | K7: =IFERROR(DATEDIF(DATEVALUE(D7 & "-" & C7 & "-" & B7), DATE(2023, 6, 8), "Y"), "No Data") -> 21 | M7: charges | N7: =COUNTIF(G3:G2345,"~?") -> 0
A8: Id2329 | B8: 1993 | C8: Jun | D8: 1 | E8: =TEXT(DATEVALUE(D8 & "-" & C8 & "-" & B8), "dd/mm/yy") -> 01/06/93 | F8: 0 | G8: 650 | H8: tier - 3 | I8: tier - 3 | J8: R1013 | K8: =IFERROR(DATEDIF(DATEVALUE(D8 & "-" & C8 & "-" & B8), DATE(2023, 6, 8), "Y"), "No Data") -> 30 | M8: Hospital tier | N8: =COUNTIF(H3:H2345,"~?") -> 0
A9: Id2328 | B9: 1995 | C9: Jul | D9: 4 | E9: =TEXT(DATEVALUE(D9 & "-" & C9 & "-" & B9), "dd/mm/yy") -> 04/07/95 | F9: 0 | G9: 650 | H9: tier - 3 | I9: tier - 3 | J9: R1013 | K9: =IFERROR(DATEDIF(DATEVALUE(D9 & "-" & C9 & "-" & B9), DATE(2023, 6, 8), "Y"), "No Data") -> 27 | M9: City tier | N9: =COUNTIF(I3:I2345,"~?") -> 0
A10: Id2327 | B10: 2002 | C10: Nov | D10: 29 | E10: =TEXT(DATEVALUE(D10 & "-" & C10 & "-" & B10), "dd/mm/yy") -> 29/11/02 | F10: 0 | G10: 668 | H10: tier - 3 | I10: tier - 2 | J10: R1012 | K10: =IFERROR(DATEDIF(DATEVALUE(D10 & "-" & C10 & "-" & B10), DATE(2023, 6, 8), "Y"), "No Data") -> 20 | M10: State ID | N10: =COUNTIF(J3:J2345,"~?") -> 0
A11: Id2326 | B11: 1997 | C11: Nov | D11: 9 | E11: =TEXT(DATEVALUE(D11 & "-" & C11 & "-" & B11), "dd/mm/yy") -> 09/11/97 | F11: 0 | G11: 670 | H11: tier - 3 | I11: tier - 3 | J11: R1013 | K11: =IFERROR(DATEDIF(DATEVALUE(D11 & "-" & C11 & "-" & B11), DATE(2023, 6, 8), "Y"), "No Data") -> 25
A12: Id2325 | B12: 2001 | C12: Sep | D12: 12 | E12: =TEXT(DATEVALUE(D12 & "-" & C12 & "-" & B12), "dd/mm/yy") -> 12/09/01 | F12: 0 | G12: 687.54 | H12: tier - 3 | I12: tier - 2 | J12: R1013 | K12: =IFERROR(DATEDIF(DATEVALUE(D12 & "-" & C12 & "-" & B12), DATE(2023, 6, 8), "Y"), "No Data") -> 21
A13: Id2324 | B13: 1999 | C13: Dec | D13: 26 | E13: =TEXT(DATEVALUE(D13 & "-" & C13 & "-" & B13), "dd/mm/yy") -> 26/12/99 | F13: 0 | G13: 700 | H13: tier - 2 | I13: tier - 3 | J13: R1013 | K13: =IFERROR(DATEDIF(DATEVALUE(D13 & "-" & C13 & "-" & B13), DATE(2023, 6, 8), "Y"), "No Data") -> 23
A14: Id2323 | B14: 1999 | C14: Dec | D14: 14 | E14: =TEXT(DATEVALUE(D14 & "-" & C14 & "-" & B14), "dd/mm/yy") -> 14/12/99 | F14: 0 | G14: 722.99 | H14: tier - 3 | I14: tier - 1 | J14: R1013 | K14: =IFERROR(DATEDIF(DATEVALUE(D14 & "-" & C14 & "-" & B14), DATE(2023, 6, 8), "Y"), "No Data") -> 23
A15: Id2322 | B15: 2002 | C15: 0 | D15: 19 | E15: =TEXT(DATEVALUE(D15 & "-" & C15 & "-" & B15), "dd/mm/yy") -> #VALUE! | F15: 0 | G15: 750 | H15: tier - 3 | I15: tier - 1 | J15: R1012 | K15: =IFERROR(DATEDIF(DATEVALUE(D15 & "-" & C15 & "-" & B15), DATE(2023, 6, 8), "Y"), "No Data") -> No Data
A16: Id2321 | B16: 1993 | C16: Aug | D16: 9 | E16: =TEXT(DATEVALUE(D16 & "-" & C16 & "-" & B16), "dd/mm/yy") -> 09/08/93 | F16: 0 | G16: 760 | H16: tier - 3 | I16: tier - 1 | J16: R1013 | K16: =IFERROR(DATEDIF(DATEVALUE(D16 & "-" & C16 & "-" & B16), DATE(2023, 6, 8), "Y"), "No Data") -> 29
A17: Id2320 | B17: 1996 | C17: Oct | D17: 22 | E17: =TEXT(DATEVALUE(D17 & "-" & C17 & "-" & B17), "dd/mm/yy") -> 22/10/96 | F17: 0 | G17: 760 | H17: tier - 3 | I17: tier - 3 | J17: R1013 | K17: =IFERROR(DATEDIF(DATEVALUE(D17 & "-" & C17 & "-" & B17), DATE(2023, 6, 8), "Y"), "No Data") -> 26
A18: Id2319 | B18: 1993 | C18: Jun | D18: 28 | E18: =TEXT(DATEVALUE(D18 & "-" & C18 & "-" & B18), "dd/mm/yy") -> 28/06/93 | F18: 0 | G18: 770 | H18: tier - 3 | I18: tier - 3 | J18: R1013 | K18: =IFERROR(DATEDIF(DATEVALUE(D18 & "-" & C18 & "-" & B18), DATE(2023, 6, 8), "Y"), "No Data") -> 29
A19: Id2318 | B19: 1996 | C19: 0 | D19: 18 | E19: =TEXT(DATEVALUE(D19 & "-" & C19 & "-" & B19), "dd/mm/yy") -> #VALUE! | F19: 0 | G19: 770.38 | H19: tier - 3 | I19: tier - 2 | J19: R1012 | K19: =IFERROR(DATEDIF(DATEVALUE(D19 & "-" & C19 & "-" & B19), DATE(2023, 6, 8), "Y"), "No Data") -> No Data
A20: Id2317 | B20: 1995 | C20: Dec | D20: 7 | E20: =TEXT(DATEVALUE(D20 & "-" & C20 & "-" & B20), "dd/mm/yy") -> 07/12/95 | F20: 0 | G20: 773.54 | H20: tier - 3 | I20: tier - 2 | J20: R1013 | K20: =IFERROR(DATEDIF(DATEVALUE(D20 & "-" & C20 & "-" & B20), DATE(2023, 6, 8), "Y"), "No Data") -> 27
A21: Id2316 | B21: 2004 | C21: Oct | D21: 7 | E21: =TEXT(DATEVALUE(D21 & "-" & C21 & "-" & B21), "dd/mm/yy") -> 07/10/04 | F21: 0 | G21: 830.52 | H21: tier - 3 | I21: tier - 2 | J21: R1011 | K21: =IFERROR(DATEDIF(DATEVALUE(D21 & "-" & C21 & "-" & B21), DATE(2023, 6, 8), "Y"), "No Data") -> 18
A22: Id2315 | B22: 2000 | C22: Nov | D22: 18 | E22: =TEXT(DATEVALUE(D22 & "-" & C22 & "-" & B22), "dd/mm/yy") -> 18/11/00 | F22: 0 | G22: 865.41 | H22: tier - 3 | I22: tier - 1 | J22: R1013 | K22: =IFERROR(DATEDIF(DATEVALUE(D22 & "-" & C22 & "-" & B22), DATE(2023, 6, 8), "Y"), "No Data") -> 22
A23: Id2314 | B23: 1993 | C23: Nov | D23: 27 | E23: =TEXT(DATEVALUE(D23 & "-" & C23 & "-" & B23), "dd/mm/yy") -> 27/11/93 | F23: 0 | G23: 896.21 | H23: tier - 3 | I23: tier - 1 | J23: R1013 | K23: =IFERROR(DATEDIF(DATEVALUE(D23 & "-" & C23 & "-" & B23), DATE(2023, 6, 8), "Y"), "No Data") -> 29
A24: Id2313 | B24: 1994 | C24: Oct | D24: 30 | E24: =TEXT(DATEVALUE(D24 & "-" & C24 & "-" & B24), "dd/mm/yy") -> 30/10/94 | F24: 0 | G24: 915.07 | H24: tier - 3 | I24: tier - 1 | J24: R1013 | K24: =IFERROR(DATEDIF(DATEVALUE(D24 & "-" & C24 & "-" & B24), DATE(2023, 6, 8), "Y"), "No Data") -> 28
A25: Id2312 | B25: 1995 | C25: Oct | D25: 28 | E25: =TEXT(DATEVALUE(D25 & "-" & C25 & "-" & B25), "dd/mm/yy") -> 28/10/95 | F25: 0 | G25: 928.59 | H25: tier - 3 | I25: tier - 1 | J25: R1013 | K25: =IFERROR(DATEDIF(DATEVALUE(D25 & "-" & C25 & "-" & B25), DATE(2023, 6, 8), "Y"), "No Data") -> 27
A26: Id2311 | B26: 2001 | C26: Aug | D26: 19 | E26: =TEXT(DATEVALUE(D26 & "-" & C26 & "-" & B26), "dd/mm/yy") -> 19/08/01 | F26: 0 | G26: 964.71 | H26: tier - 3 | I26: tier - 2 | J26: R1013 | K26: =IFERROR(DATEDIF(DATEVALUE(D26 & "-" & C26 & "-" & B26), DATE(2023, 6, 8), "Y"), "No Data") -> 21
A27: Id2310 | B27: 1994 | C27: Nov | D27: 22 | E27: =TEXT(DATEVALUE(D27 & "-" & C27 & "-" & B27), "dd/mm/yy") -> 22/11/94 | F27: 0 | G27: 1006.65 | H27: tier - 3 | I27: tier - 2 | J27: R1013 | K27: =IFERROR(DATEDIF(DATEVALUE(D27 & "-" & C27 & "-" & B27), DATE(2023, 6, 8), "Y"), "No Data") -> 28
A28: Id2309 | B28: 2000 | C28: Oct | D28: 9 | E28: =TEXT(DATEVALUE(D28 & "-" & C28 & "-" & B28), "dd/mm/yy") -> 09/10/00 | F28: 0 | G28: 1012 | H28: tier - 3 | I28: tier - 2 | J28: R1013 | K28: =IFERROR(DATEDIF(DATEVALUE(D28 & "-" & C28 & "-" & B28), DATE(2023, 6, 8), "Y"), "No Data") -> 22
A29: Id2308 | B29: 1999 | C29: Aug | D29: 5 | E29: =TEXT(DATEVALUE(D29 & "-" & C29 & "-" & B29), "dd/mm/yy") -> 05/08/99 | F29: 0 | G29: 1019 | H29: tier - 3 | I29: tier - 2 | J29: R1013 | K29: =IFERROR(DATEDIF(DATEVALUE(D29 & "-" & C29 & "-" & B29), DATE(2023, 6, 8), "Y"), "No Data") -> 23
A30: Id2307 | B30: 1995 | C30: Oct | D30: 5 | E30: =TEXT(DATEVALUE(D30 & "-" & C30 & "-" & B30), "dd/mm/yy") -> 05/10/95 | F30: 0 | G30: 1033.74 | H30: tier - 3 | I30: tier - 1 | J30: R1013 | K30: =IFERROR(DATEDIF(DATEVALUE(D30 & "-" & C30 & "-" & B30), DATE(2023, 6, 8), "Y"), "No Data") -> 27
A31: Id2306 | B31: 1994 | C31: Nov | D31: 17 | E31: =TEXT(DATEVALUE(D31 & "-" & C31 & "-" & B31), "dd/mm/yy") -> 17/11/94 | F31: 0 | G31: 1044 | H31: tier - 3 | I31: tier - 2 | J31: R1013 | K31: =IFERROR(DATEDIF(DATEVALUE(D31 & "-" & C31 & "-" & B31), DATE(2023, 6, 8), "Y"), "No Data") -> 28
... A46: Id2291 | B46: 2002 | C46: Aug | D46: 11 | E46: =TEXT(DATEVALUE(D46 & "-" & C46 & "-" & B46), "dd/mm/yy") -> 11/08/02 | F46: 0 | G46: 1137 | H46: tier - 3 | I46: tier - 1 | J46: R1013 | K46: =IFERROR(DATEDIF(DATEVALUE(D46 & "-" & C46 & "-" & B46), DATE(2023, 6, 8), "Y"), "No Data") -> 20
A47: 0 | B47: 2004 | C47: Nov | D47: 6 | E47: =TEXT(DATEVALUE(D47 & "-" & C47 & "-" & B47), "dd/mm/yy") -> 06/11/04 | F47: 0 | G47: 1137.01 | H47: tier - 3 | I47: tier - 1 | J47: R1013 | K47: =IFERROR(DATEDIF(DATEVALUE(D47 & "-" & C47 & "-" & B47), DATE(2023, 6, 8), "Y"), "No Data") -> 18
A48: Id2290 | B48: 2004 | C48: Oct | D48: 15 | E48: =TEXT(DATEVALUE(D48 & "-" & C48 & "-" & B48), "dd/mm/yy") -> 15/10/04 | F48: 0 | G48: 1137.01 | H48: tier - 3 | I48: tier - 1 | J48: R1013 | K48: =IFERROR(DATEDIF(DATEVALUE(D48 & "-" & C48 & "-" & B48), DATE(2023, 6, 8), "Y"), "No Data") -> 18
A49: Id2289 | B49: 2004 | C49: Nov | D49: 27 | E49: =TEXT(DATEVALUE(D49 & "-" & C49 & "-" & B49), "dd/mm/yy") -> 27/11/04 | F49: 0 | G49: 1137.47 | H49: tier - 3 | I49: tier - 2 | J49: R1013 | K49: =IFERROR(DATEDIF(DATEVALUE(D49 & "-" & C49 & "-" & B49), DATE(2023, 6, 8), "Y"), "No Data") -> 18
A50: Id2288 | B50: 2001 | C50: Oct | D50: 25 | E50: =TEXT(DATEVALUE(D50 & "-" & C50 & "-" & B50), "dd/mm/yy") -> 25/10/01 | F50: 0 | G50: 1141 | H50: tier - 3 | I50: tier - 1 | J50: R1013 | K50: =IFERROR(DATEDIF(DATEVALUE(D50 & "-" & C50 & "-" & B50), DATE(2023, 6, 8), "Y"), "No Data") -> 21
A51: Id2287 | B51: 2004 | C51: Sep | D51: 12 | E51: =TEXT(DATEVALUE(D51 & "-" & C51 & "-" & B51), "dd/mm/yy") -> 12/09/04 | F51: 0 | G51: 1141.45 | H51: tier - 3 | I51: tier - 3 | J51: R1013 | K51: =IFERROR(DATEDIF(DATEVALUE(D51 & "-" & C51 & "-" & B51), DATE(2023, 6, 8), "Y"), "No Data") -> 18
A52: Id2286 | B52: 2002 | C52: Oct | D52: 1 | E52: =TEXT(DATEVALUE(D52 & "-" & C52 & "-" & B52), "dd/mm/yy") -> 01/10/02 | F52: 0 | G52: 1142 | H52: tier - 3 | I52: tier - 2 | J52: R1011 | K52: =IFERROR(DATEDIF(DATEVALUE(D52 & "-" & C52 & "-" & B52), DATE(2023, 6, 8), "Y"), "No Data") -> 20
A53: Id2285 | B53: 2004 | C53: Jun | D53: 10 | E53: =TEXT(DATEVALUE(D53 & "-" & C53 & "-" & B53), "dd/mm/yy") -> 10/06/04 | F53: 0 | G53: 1146.8 | H53: tier - 2 | I53: tier - 2 | J53: R1013 | K53: =IFERROR(DATEDIF(DATEVALUE(D53 & "-" & C53 & "-" & B53), DATE(2023, 6, 8), "Y"), "No Data") -> 18
A54: Id2284 | B54: 2003 | C54: Jun | D54: 12 | E54: =TEXT(DATEVALUE(D54 & "-" & C54 & "-" & B54), "dd/mm/yy") -> 12/06/03 | F54: 0 | G54: 1149 | H54: tier - 2 | I54: tier - 1 | J54: R1012 | K54: =IFERROR(DATEDIF(DATEVALUE(D54 & "-" & C54 & "-" & B54), DATE(2023, 6, 8), "Y"), "No Data") -> 19
...

Sheet Healthcare
A1: Customer ID | B1: First Name | C1: BMI | D1: HBA1C | E1: Heart Issues | F1: Any Transplants | G1: Cancer History | H1: Number of Major Surgeries | I1: Smoker | J1: Weight Status | K1: City tier | L1: State ID | M1: Date of birth | N1: Age | O1: charges | P1: Hospital tier
A2: Id1 | B2: {=_xlfn.XLOOKUP($A2, 'Customer Names'!$A:$A, 'Customer Names'!B:B, "No Data")} -> Hawks | C2: {=_xlfn.XLOOKUP($A2, 'Medical Examinations'!$A:$A, 'Medical Examinations'!B:B, "No Data")} -> 47.41 | D2: {=_xlfn.XLOOKUP($A2, 'Medical Examinations'!$A:$A, 'Medical Examinations'!C:C, "No Data")} -> 7.47 | E2: {=_xlfn.XLOOKUP($A2, 'Medical Examinations'!$A:$A, 'Medical Examinations'!D:D, "No Data")} -> No | F2: {=_xlfn.XLOOKUP($A2, 'Medical Examinations'!$A:$A, 'Medical Examinations'!E:E, "No Data")} -> No | G2: {=_xlfn.XLOOKUP($A2, 'Medical Examinations'!$A:$A, 'Medical Examinations'!F:F, "No Data")} -> No | H2: {=_xlfn.XLOOKUP($A2, 'Medical Examinations'!$A:$A, 'Medical Examinations'!G:G, "No Data")} -> 0 | I2: {=_xlfn.XLOOKUP($A2, 'Medical Examinations'!$A:$A, 'Medical Examinations'!H:H, "No Data")} -> yes | J2: {=_xlfn.XLOOKUP($A2, 'Medical Examinations'!$A:$A, 'Medical Examinations'!I:I, "No Data")} -> Obesity | K2: {=_xlfn.XLOOKUP($A2, 'Hospitalisation Details'!$A:$A, 'Hospitalisation Details'!I:I, "No Data")} -> tier - 3 | L2: {=_xlfn.XLOOKUP($A2, 'Hospitalisation Details'!$A:$A, 'Hospitalisation Details'!J:J, "No Data")} -> R1013 | M2: {=_xlfn.XLOOKUP($A2, 'Hospitalisation Details'!$A:$A, 'Hospitalisation Details'!E:E, "No Data")} -> 12/10/68 | N2: {=_xlfn.XLOOKUP($A2, 'Hospitalisation Details'!$A:$A, 'Hospitalisation Details'!K:K, "No Data")} -> 54 | O2: {=_xlfn.XLOOKUP($A2, 'Hospitalisation Details'!$A:$A, 'Hospitalisation Details'!G:G, "No Data")} -> 63770.43 | P2: {=_xlfn.XLOOKUP($A2, 'Hospitalisation Details'!$A:$A, 'Hospitalisation Details'!H:H, "No Data")} -> tier - 1
A3: Id2 | B3: {=_xlfn.XLOOKUP($A3, 'Customer Names'!$A:$A, 'Customer Names'!B:B, "No Data")} -> Lehner | C3: {=_xlfn.XLOOKUP($A3, 'Medical Examinations'!$A:$A, 'Medical Examinations'!B:B, "No Data")} -> 30.36 | D3: {=_xlfn.XLOOKUP($A3, 'Medical Examinations'!$A:$A, 'Medical Examinations'!C:C, "No Data")} -> 5.77 | E3: {=_xlfn.XLOOKUP($A3, 'Medical Examinations'!$A:$A, 'Medical Examinations'!D:D, "No Data")} -> No | F3: {=_xlfn.XLOOKUP($A3, 'Medical Examinations'!$A:$A, 'Medical Examinations'!E:E, "No Data")} -> No | G3: {=_xlfn.XLOOKUP($A3, 'Medical Examinations'!$A:$A, 'Medical Examinations'!F:F, "No Data")} -> No | H3: {=_xlfn.XLOOKUP($A3, 'Medical Examinations'!$A:$A, 'Medical Examinations'!G:G, "No Data")} -> 0 | I3: {=_xlfn.XLOOKUP($A3, 'Medical Examinations'!$A:$A, 'Medical Examinations'!H:H, "No Data")} -> yes | J3: {=_xlfn.XLOOKUP($A3, 'Medical Examinations'!$A:$A, 'Medical Examinations'!I:I, "No Data")} -> Obesity | K3: {=_xlfn.XLOOKUP($A3, 'Hospitalisation Details'!$A:$A, 'Hospitalisation Details'!I:I, "No Data")} -> tier - 3 | L3: {=_xlfn.XLOOKUP($A3, 'Hospitalisation Details'!$A:$A, 'Hospitalisation Details'!J:J, "No Data")} -> R1013 | M3: {=_xlfn.XLOOKUP($A3, 'Hospitalisation Details'!$A:$A, 'Hospitalisation Details'!E:E, "No Data")} -> 08/06/77 | N3: {=_xlfn.XLOOKUP($A3, 'Hospitalisation Details'!$A:$A, 'Hospitalisation Details'!K:K, "No Data")} -> 46 | O3: {=_xlfn.XLOOKUP($A3, 'Hospitalisation Details'!$A:$A, 'Hospitalisation Details'!G:G, "No Data")} -> 62592.87 | P3: {=_xlfn.XLOOKUP($A3, 'Hospitalisation Details'!$A:$A, 'Hospitalisation Details'!H:H, "No Data")} -> tier - 2
A4: Id3 | B4: {=_xlfn.XLOOKUP($A4, 'Customer Names'!$A:$A, 'Customer Names'!B:B, "No Data")} -> Lu | C4: {=_xlfn.XLOOKUP($A4, 'Medical Examinations'!$A:$A, 'Medical Examinations'!B:B, "No Data")} -> 34.485 | D4: {=_xlfn.XLOOKUP($A4, 'Medical Examinations'!$A:$A, 'Medical Examinations'!C:C, "No Data")} -> 11.87 | E4: {=_xlfn.XLOOKUP($A4, 'Medical Examinations'!$A:$A, 'Medical Examinations'!D:D, "No Data")} -> yes | F4: {=_xlfn.XLOOKUP($A4, 'Medical Examinations'!$A:$A, 'Medical Examinations'!E:E, "No Data")} -> No | G4: {=_xlfn.XLOOKUP($A4, 'Medical Examinations'!$A:$A, 'Medical Examinations'!F:F, "No Data")} -> No | H4: {=_xlfn.XLOOKUP($A4, 'Medical Examinations'!$A:$A, 'Medical Examinations'!G:G, "No Data")} -> 2 | I4: {=_xlfn.XLOOKUP($A4, 'Medical Examinations'!$A:$A, 'Medical Examinations'!H:H, "No Data")} -> yes | J4: {=_xlfn.XLOOKUP($A4, 'Medical Examinations'!$A:$A, 'Medical Examinations'!I:I, "No Data")} -> Obesity | K4: {=_xlfn.XLOOKUP($A4, 'Hospitalisation Details'!$A:$A, 'Hospitalisation Details'!I:I, "No Data")} -> tier - 1 | L4: {=_xlfn.XLOOKUP($A4, 'Hospitalisation Details'!$A:$A, 'Hospitalisation Details'!J:J, "No Data")} -> R1012 | M4: No Data | N4: {=_xlfn.XLOOKUP($A4, 'Hospitalisation Details'!$A:$A, 'Hospitalisation Details'!K:K, "No Data")} -> No Data | O4: {=_xlfn.XLOOKUP($A4, 'Hospitalisation Details'!$A:$A, 'Hospitalisation Details'!G:G, "No Data")} -> 60021.4 | P4: {=_xlfn.XLOOKUP($A4, 'Hospitalisation Details'!$A:$A, 'Hospitalisation Details'!H:H, "No Data")} -> tier - 1
A5: Id4 | B5: {=_xlfn.XLOOKUP($A5, 'Customer Names'!$A:$A, 'Customer Names'!B:B, "No Data")} -> Osborne | C5: {=_xlfn.XLOOKUP($A5, 'Medical Examinations'!$A:$A, 'Medical Examinations'!B:B, "No Data")} -> 38.095 | D5: {=_xlfn.XLOOKUP($A5, 'Medical Examinations'!$A:$A, 'Medical Examinations'!C:C, "No Data")} -> 6.05 | E5: {=_xlfn.XLOOKUP($A5, 'Medical Examinations'!$A:$A, 'Medical Examinations'!D:D, "No Data")} -> No | F5: {=_xlfn.XLOOKUP($A5, 'Medical Examinations'!$A:$A, 'Medical Examinations'!E:E, "No Data")} -> No | G5: {=_xlfn.XLOOKUP($A5, 'Medical Examinations'!$A:$A, 'Medical Examinations'!F:F, "No Data")} -> No | H5: {=_xlfn.XLOOKUP($A5, 'Medical Examinations'!$A:$A, 'Medical Examinations'!G:G, "No Data")} -> 0 | I5: {=_xlfn.XLOOKUP($A5, 'Medical Examinations'!$A:$A, 'Medical Examinations'!H:H, "No Data")} -> yes | J5: {=_xlfn.XLOOKUP($A5, 'Medical Examinations'!$A:$A, 'Medical Examinations'!I:I, "No Data")} -> Obesity | K5: {=_xlfn.XLOOKUP($A5, 'Hospitalisation Details'!$A:$A, 'Hospitalisation Details'!I:I, "No Data")} -> tier - 3 | L5: {=_xlfn.XLOOKUP($A5, 'Hospitalisation Details'!$A:$A, 'Hospitalisation Details'!J:J, "No Data")} -> R1024 | M5: {=_xlfn.XLOOKUP($A5, 'Hospitalisation Details'!$A:$A, 'Hospitalisation Details'!E:E, "No Data")} -> 06/06/91 | N5: {=_xlfn.XLOOKUP($A5, 'Hospitalisation Details'!$A:$A, 'Hospitalisation Details'!K:K, "No Data")} -> 32 | O5: {=_xlfn.XLOOKUP($A5, 'Hospitalisation Details'!$A:$A, 'Hospitalisation Details'!G:G, "No Data")} -> 58571.07 | P5: {=_xlfn.XLOOKUP($A5, 'Hospitalisation Details'!$A:$A, 'Hospitalisation Details'!H:H, "No Data")} -> tier - 1
A6: Id5 | B6: {=_xlfn.XLOOKUP($A6, 'Customer Names'!$A:$A, 'Customer Names'!B:B, "No Data")} -> Kadala | C6: {=_xlfn.XLOOKUP($A6, 'Medical Examinations'!$A:$A, 'Medical Examinations'!B:B, "No Data")} -> 35.53 | D6: {=_xlfn.XLOOKUP($A6, 'Medical Examinations'!$A:$A, 'Medical Examinations'!C:C, "No Data")} -> 5.45 | E6: {=_xlfn.XLOOKUP($A6, 'Medical Examinations'!$A:$A, 'Medical Examinations'!D:D, "No Data")} -> No | F6: {=_xlfn.XLOOKUP($A6, 'Medical Examinations'!$A:$A, 'Medical Examinations'!E:E, "No Data")} -> No | G6: {=_xlfn.XLOOKUP($A6, 'Medical Examinations'!$A:$A, 'Medical Examinations'!F:F, "No Data")} -> No | H6: {=_xlfn.XLOOKUP($A6, 'Medical Examinations'!$A:$A, 'Medical Examinations'!G:G, "No Data")} -> 0 | I6: {=_xlfn.XLOOKUP($A6, 'Medical Examinations'!$A:$A, 'Medical Examinations'!H:H, "No Data")} -> yes | J6: {=_xlfn.XLOOKUP($A6, 'Medical Examinations'!$A:$A, 'Medical Examinations'!I:I, "No Data")} -> Obesity | K6: {=_xlfn.XLOOKUP($A6, 'Hospitalisation Details'!$A:$A, 'Hospitalisation Details'!I:I, "No Data")} -> tier - 2 | L6: {=_xlfn.XLOOKUP($A6, 'Hospitalisation Details'!$A:$A, 'Hospitalisation Details'!J:J, "No Data")} -> R1012 | M6: {=_xlfn.XLOOKUP($A6, 'Hospitalisation Details'!$A:$A, 'Hospitalisation Details'!E:E, "No Data")} -> 19/06/89 | N6: {=_xlfn.XLOOKUP($A6, 'Hospitalisation Details'!$A:$A, 'Hospitalisation Details'!K:K, "No Data")} -> 33 | O6: {=_xlfn.XLOOKUP($A6, 'Hospitalisation Details'!$A:$A, 'Hospitalisation Details'!G:G, "No Data")} -> 55135.4 | P6: {=_xlfn.XLOOKUP($A6, 'Hospitalisation Details'!$A:$A, 'Hospitalisation Details'!H:H, "No Data")} -> tier - 1
A7: Id6 | B7: {=_xlfn.XLOOKUP($A7, 'Customer Names'!$A:$A, 'Customer Names'!B:B, "No Data")} -> Baker | C7: {=_xlfn.XLOOKUP($A7, 'Medical Examinations'!$A:$A, 'Medical Examinations'!B:B, "No Data")} -> 32.8 | D7: {=_xlfn.XLOOKUP($A7, 'Medical Examinations'!$A:$A, 'Medical Examinations'!C:C, "No Data")} -> 6.59 | E7: {=_xlfn.XLOOKUP($A7, 'Medical Examinations'!$A:$A, 'Medical Examinations'!D:D, "No Data")} -> No | F7: {=_xlfn.XLOOKUP($A7, 'Medical Examinations'!$A:$A, 'Medical Examinations'!E:E, "No Data")} -> No | G7: {=_xlfn.XLOOKUP($A7, 'Medical Examinations'!$A:$A, 'Medical Examinations'!F:F, "No Data")} -> No | H7: {=_xlfn.XLOOKUP($A7, 'Medical Examinations'!$A:$A, 'Medical Examinations'!G:G, "No Data")} -> 0 | I7: {=_xlfn.XLOOKUP($A7, 'Medical Examinations'!$A:$A, 'Medical Examinations'!H:H, "No Data")} -> yes | J7: {=_xlfn.XLOOKUP($A7, 'Medical Examinations'!$A:$A, 'Medical Examinations'!I:I, "No Data")} -> Obesity | K7: {=_xlfn.XLOOKUP($A7, 'Hospitalisation Details'!$A:$A, 'Hospitalisation Details'!I:I, "No Data")} -> tier - 3 | L7: {=_xlfn.XLOOKUP($A7, 'Hospitalisation Details'!$A:$A, 'Hospitalisation Details'!J:J, "No Data")} -> R1011 | M7: {=_xlfn.XLOOKUP($A7, 'Hospitalisation Details'!$A:$A, 'Hospitalisation Details'!E:E, "No Data")} -> 04/08/62 | N7: {=_xlfn.XLOOKUP($A7, 'Hospitalisation Details'!$A:$A, 'Hospitalisation Details'!K:K, "No Data")} -> 60 | O7: {=_xlfn.XLOOKUP($A7, 'Hospitalisation Details'!$A:$A, 'Hospitalisation Details'!G:G, "No Data")} -> 52590.83 | P7: {=_xlfn.XLOOKUP($A7, 'Hospitalisation Details'!$A:$A, 'Hospitalisation Details'!H:H, "No Data")} -> tier - 1
A8: Id7 | B8: {=_xlfn.XLOOKUP($A8, 'Customer Names'!$A:$A, 'Customer Names'!B:B, "No Data")} -> Macpherson | C8: {=_xlfn.XLOOKUP($A8, 'Medical Examinations'!$A:$A, 'Medical Examinations'!B:B, "No Data")} -> 36.4 | D8: {=_xlfn.XLOOKUP($A8, 'Medical Examinations'!$A:$A, 'Medical Examinations'!C:C, "No Data")} -> 6.07 | E8: {=_xlfn.XLOOKUP($A8, 'Medical Examinations'!$A:$A, 'Medical Examinations'!D:D, "No Data")} -> No | F8: {=_xlfn.XLOOKUP($A8, 'Medical Examinations'!$A:$A, 'Medical Examinations'!E:E, "No Data")} -> No | G8: {=_xlfn.XLOOKUP($A8, 'Medical Examinations'!$A:$A, 'Medical Examinations'!F:F, "No Data")} -> No | H8: {=_xlfn.XLOOKUP($A8, 'Medical Examinations'!$A:$A, 'Medical Examinations'!G:G, "No Data")} -> 0 | I8: {=_xlfn.XLOOKUP($A8, 'Medical Examinations'!$A:$A, 'Medical Examinations'!H:H, "No Data")} -> yes | J8: {=_xlfn.XLOOKUP($A8, 'Medical Examinations'!$A:$A, 'Medical Examinations'!I:I, "No Data")} -> Obesity | K8: {=_xlfn.XLOOKUP($A8, 'Hospitalisation Details'!$A:$A, 'Hospitalisation Details'!I:I, "No Data")} -> tier - 3 | L8: {=_xlfn.XLOOKUP($A8, 'Hospitalisation Details'!$A:$A, 'Hospitalisation Details'!J:J, "No Data")} -> R1011 | M8: {=_xlfn.XLOOKUP($A8, 'Hospitalisation Details'!$A:$A, 'Hospitalisation Details'!E:E, "No Data")} -> 27/10/94 | N8: {=_xlfn.XLOOKUP($A8, 'Hospitalisation Details'!$A:$A, 'Hospitalisation Details'!K:K, "No Data")} -> 28 | O8: {=_xlfn.XLOOKUP($A8, 'Hospitalisation Details'!$A:$A, 'Hospitalisation Details'!G:G, "No Data")} -> 51194.56 | P8: {=_xlfn.XLOOKUP($A8, 'Hospitalisation Details'!$A:$A, 'Hospitalisation Details'!H:H, "No Data")} -> tier - 1
A9: Id8 | B9: {=_xlfn.XLOOKUP($A9, 'Customer Names'!$A:$A, 'Customer Names'!B:B, "No Data")} -> Hallman | C9: {=_xlfn.XLOOKUP($A9, 'Medical Examinations'!$A:$A, 'Medical Examinations'!B:B, "No Data")} -> 36.96 | D9: {=_xlfn.XLOOKUP($A9, 'Medical Examinations'!$A:$A, 'Medical Examinations'!C:C, "No Data")} -> 7.93 | E9: {=_xlfn.XLOOKUP($A9, 'Medical Examinations'!$A:$A, 'Medical Examinations'!D:D, "No Data")} -> No | F9: {=_xlfn.XLOOKUP($A9, 'Medical Examinations'!$A:$A, 'Medical Examinations'!E:E, "No Data")} -> No | G9: {=_xlfn.XLOOKUP($A9, 'Medical Examinations'!$A:$A, 'Medical Examinations'!F:F, "No Data")} -> No | H9: {=_xlfn.XLOOKUP($A9, 'Medical Examinations'!$A:$A, 'Medical Examinations'!G:G, "No Data")} -> 3 | I9: {=_xlfn.XLOOKUP($A9, 'Medical Examinations'!$A:$A, 'Medical Examinations'!H:H, "No Data")} -> yes | J9: {=_xlfn.XLOOKUP($A9, 'Medical Examinations'!$A:$A, 'Medical Examinations'!I:I, "No Data")} -> Obesity | K9: {=_xlfn.XLOOKUP($A9, 'Hospitalisation Details'!$A:$A, 'Hospitalisation Details'!I:I, "No Data")} -> tier - 2 | L9: {=_xlfn.XLOOKUP($A9, 'Hospitalisation Details'!$A:$A, 'Hospitalisation Details'!J:J, "No Data")} -> R1013 | M9: {=_xlfn.XLOOKUP($A9, 'Hospitalisation Details'!$A:$A, 'Hospitalisation Details'!E:E, "No Data")} -> 27/06/58 | N9: {=_xlfn.XLOOKUP($A9, 'Hospitalisation Details'!$A:$A, 'Hospitalisation Details'!K:K, "No Data")} -> 64 | O9: {=_xlfn.XLOOKUP($A9, 'Hospitalisation Details'!$A:$A, 'Hospitalisation Details'!G:G, "No Data")} -> 49577.66 | P9: {=_xlfn.XLOOKUP($A9, 'Hospitalisation Details'!$A:$A, 'Hospitalisation Details'!H:H, "No Data")} -> tier - 2
A10: Id9 | B10: {=_xlfn.XLOOKUP($A10, 'Customer Names'!$A:$A, 'Customer Names'!B:B, "No Data")} -> Moran | C10: {=_xlfn.XLOOKUP($A10, 'Medical Examinations'!$A:$A, 'Medical Examinations'!B:B, "No Data")} -> 41.14 | D10: {=_xlfn.XLOOKUP($A10, 'Medical Examinations'!$A:$A, 'Medical Examinations'!C:C, "No Data")} -> 9.58 | E10: {=_xlfn.XLOOKUP($A10, 'Medical Examinations'!$A:$A, 'Medical Examinations'!D:D, "No Data")} -> yes | F10: {=_xlfn.XLOOKUP($A10, 'Medical Examinations'!$A:$A, 'Medical Examinations'!E:E, "No Data")} -> No | G10: {=_xlfn.XLOOKUP($A10, 'Medical Examinations'!$A:$A, 'Medical Examinations'!F:F, "No Data")} -> Yes | H10: {=_xlfn.XLOOKUP($A10, 'Medical Examinations'!$A:$A, 'Medical Examinations'!G:G, "No Data")} -> 1 | I10: {=_xlfn.XLOOKUP($A10, 'Medical Examinations'!$A:$A, 'Medical Examinations'!H:H, "No Data")} -> yes | J10: {=_xlfn.XLOOKUP($A10, 'Medical Examinations'!$A:$A, 'Medical Examinations'!I:I, "No Data")} -> Obesity | K10: {=_xlfn.XLOOKUP($A10, 'Hospitalisation Details'!$A:$A, 'Hospitalisation Details'!I:I, "No Data")} -> tier - 2 | L10: {=_xlfn.XLOOKUP($A10, 'Hospitalisation Details'!$A:$A, 'Hospitalisation Details'!J:J, "No Data")} -> R1013 | M10: {=_xlfn.XLOOKUP($A10, 'Hospitalisation Details'!$A:$A, 'Hospitalisation Details'!E:E, "No Data")} -> 04/09/63 | N10: {=_xlfn.XLOOKUP($A10, 'Hospitalisation Details'!$A:$A, 'Hospitalisation Details'!K:K, "No Data")} -> 59 | O10: {=_xlfn.XLOOKUP($A10, 'Hospitalisation Details'!$A:$A, 'Hospitalisation Details'!G:G, "No Data")} -> 48970.25 | P10: {=_xlfn.XLOOKUP($A10, 'Hospitalisation Details'!$A:$A, 'Hospitalisation Details'!H:H, "No Data")} -> tier - 1
A11: Id10 | B11: {=_xlfn.XLOOKUP($A11, 'Customer Names'!$A:$A, 'Customer Names'!B:B, "No Data")} -> Benner | C11: {=_xlfn.XLOOKUP($A11, 'Medical Examinations'!$A:$A, 'Medical Examinations'!B:B, "No Data")} -> 38.06 | D11: {=_xlfn.XLOOKUP($A11, 'Medical Examinations'!$A:$A, 'Medical Examinations'!C:C, "No Data")} -> 10.79 | E11: {=_xlfn.XLOOKUP($A11, 'Medical Examinations'!$A:$A, 'Medical Examinations'!D:D, "No Data")} -> No | F11: {=_xlfn.XLOOKUP($A11, 'Medical Examinations'!$A:$A, 'Medical Examinations'!E:E, "No Data")} -> No | G11: {=_xlfn.XLOOKUP($A11, 'Medical Examinations'!$A:$A, 'Medical Examinations'!F:F, "No Data")} -> No | H11: {=_xlfn.XLOOKUP($A11, 'Medical Examinations'!$A:$A, 'Medical Examinations'!G:G, "No Data")} -> 0 | I11: {=_xlfn.XLOOKUP($A11, 'Medical Examinations'!$A:$A, 'Medical Examinations'!H:H, "No Data")} -> yes | J11: {=_xlfn.XLOOKUP($A11, 'Medical Examinations'!$A:$A, 'Medical Examinations'!I:I, "No Data")} -> Obesity | K11: {=_xlfn.XLOOKUP($A11, 'Hospitalisation Details'!$A:$A, 'Hospitalisation Details'!I:I, "No Data")} -> tier - 2 | L11: {=_xlfn.XLOOKUP($A11, 'Hospitalisation Details'!$A:$A, 'Hospitalisation Details'!J:J, "No Data")} -> R1013 | M11: {=_xlfn.XLOOKUP($A11, 'Hospitalisation Details'!$A:$A, 'Hospitalisation Details'!E:E, "No Data")} -> 29/12/78 | N11: {=_xlfn.XLOOKUP($A11, 'Hospitalisation Details'!$A:$A, 'Hospitalisation Details'!K:K, "No Data")} -> 44 | O11: {=_xlfn.XLOOKUP($A11, 'Hospitalisation Details'!$A:$A, 'Hospitalisation Details'!G:G, "No Data")} -> 48885.14 | P11: {=_xlfn.XLOOKUP($A11, 'Hospitalisation Details'!$A:$A, 'Hospitalisation Details'!H:H, "No Data")} -> tier - 1
A12: Id11 | B12: {=_xlfn.XLOOKUP($A12, 'Customer Names'!$A:$A, 'Customer Names'!B:B, "No Data")} -> Fierro Vargas | C12: {=_xlfn.XLOOKUP($A12, 'Medical Examinations'!$A:$A, 'Medical Examinations'!B:B, "No Data")} -> 37.7 | D12: {=_xlfn.XLOOKUP($A12, 'Medical Examinations'!$A:$A, 'Medical Examinations'!C:C, "No Data")} -> 5.96 | E12: {=_xlfn.XLOOKUP($A12, 'Medical Examinations'!$A:$A, 'Medical Examinations'!D:D, "No Data")} -> yes | F12: {=_xlfn.XLOOKUP($A12, 'Medical Examinations'!$A:$A, 'Medical Examinations'!E:E, "No Data")} -> No | G12: {=_xlfn.XLOOKUP($A12, 'Medical Examinations'!$A:$A, 'Medical Examinations'!F:F, "No Data")} -> No | H12: {=_xlfn.XLOOKUP($A12, 'Medical Examinations'!$A:$A, 'Medical Examinations'!G:G, "No Data")} -> 2 | I12: {=_xlfn.XLOOKUP($A12, 'Medical Examinations'!$A:$A, 'Medical Examinations'!H:H, "No Data")} -> yes | J12: {=_xlfn.XLOOKUP($A12, 'Medical Examinations'!$A:$A, 'Medical Examinations'!I:I, "No Data")} -> Obesity | K12: {=_xlfn.XLOOKUP($A12, 'Hospitalisation Details'!$A:$A, 'Hospitalisation Details'!I:I, "No Data")} -> tier - 1 | L12: {=_xlfn.XLOOKUP($A12, 'Hospitalisation Details'!$A:$A, 'Hospitalisation Details'!J:J, "No Data")} -> R1011 | M12: {=_xlfn.XLOOKUP($A12, 'Hospitalisation Details'!$A:$A, 'Hospitalisation Details'!E:E, "No Data")} -> 22/07/59 | N12: {=_xlfn.XLOOKUP($A12, 'Hospitalisation Details'!$A:$A, 'Hospitalisation Details'!K:K, "No Data")} -> 63 | O12: {=_xlfn.XLOOKUP($A12, 'Hospitalisation Details'!$A:$A, 'Hospitalisation Details'!G:G, "No Data")} -> 48824.45 | P12: {=_xlfn.XLOOKUP($A12, 'Hospitalisation Details'!$A:$A, 'Hospitalisation Details'!H:H, "No Data")} -> tier - 2
A13: Id12 | B13: {=_xlfn.XLOOKUP($A13, 'Customer Names'!$A:$A, 'Customer Names'!B:B, "No Data")} -> Franz | C13: {=_xlfn.XLOOKUP($A13, 'Medical Examinations'!$A:$A, 'Medical Examinations'!B:B, "No Data")} -> 42.13 | D13: {=_xlfn.XLOOKUP($A13, 'Medical Examinations'!$A:$A, 'Medical Examinations'!C:C, "No Data")} -> 11.9 | E13: {=_xlfn.XLOOKUP($A13, 'Medical Examinations'!$A:$A, 'Medical Examinations'!D:D, "No Data")} -> No | F13: {=_xlfn.XLOOKUP($A13, 'Medical Examinations'!$A:$A, 'Medical Examinations'!E:E, "No Data")} -> No | G13: {=_xlfn.XLOOKUP($A13, 'Medical Examinations'!$A:$A, 'Medical Examinations'!F:F, "No Data")} -> No | H13: {=_xlfn.XLOOKUP($A13, 'Medical Examinations'!$A:$A, 'Medical Examinations'!G:G, "No Data")} -> 0 | I13: {=_xlfn.XLOOKUP($A13, 'Medical Examinations'!$A:$A, 'Medical Examinations'!H:H, "No Data")} -> yes | J13: {=_xlfn.XLOOKUP($A13, 'Medical Examinations'!$A:$A, 'Medical Examinations'!I:I, "No Data")} -> Obesity | K13: {=_xlfn.XLOOKUP($A13, 'Hospitalisation Details'!$A:$A, 'Hospitalisation Details'!I:I, "No Data")} -> tier - 2 | L13: {=_xlfn.XLOOKUP($A13, 'Hospitalisation Details'!$A:$A, 'Hospitalisation Details'!J:J, "No Data")} -> R1013 | M13: {=_xlfn.XLOOKUP($A13, 'Hospitalisation Details'!$A:$A, 'Hospitalisation Details'!E:E, "No Data")} -> 27/10/65 | N13: {=_xlfn.XLOOKUP($A13, 'Hospitalisation Details'!$A:$A, 'Hospitalisation Details'!K:K, "No Data")} -> 57 | O13: {=_xlfn.XLOOKUP($A13, 'Hospitalisation Details'!$A:$A, 'Hospitalisation Details'!G:G, "No Data")} -> 48675.52 | P13: {=_xlfn.XLOOKUP($A13, 'Hospitalisation Details'!$A:$A, 'Hospitalisation Details'!H:H, "No Data")} -> tier - 1
A14: Id13 | B14: {=_xlfn.XLOOKUP($A14, 'Customer Names'!$A:$A, 'Customer Names'!B:B, "No Data")} -> Foster | C14: {=_xlfn.XLOOKUP($A14, 'Medical Examinations'!$A:$A, 'Medical Examinations'!B:B, "No Data")} -> 40.92 | D14: {=_xlfn.XLOOKUP($A14, 'Medical Examinations'!$A:$A, 'Medical Examinations'!C:C, "No Data")} -> 8.41 | E14: {=_xlfn.XLOOKUP($A14, 'Medical Examinations'!$A:$A, 'Medical Examinations'!D:D, "No Data")} -> No | F14: {=_xlfn.XLOOKUP($A14, 'Medical Examinations'!$A:$A, 'Medical Examinations'!E:E, "No Data")} -> No | G14: {=_xlfn.XLOOKUP($A14, 'Medical Examinations'!$A:$A, 'Medical Examinations'!F:F, "No Data")} -> No | H14: {=_xlfn.XLOOKUP($A14, 'Medical Examinations'!$A:$A, 'Medical Examinations'!G:G, "No Data")} -> 0 | I14: {=_xlfn.XLOOKUP($A14, 'Medical Examinations'!$A:$A, 'Medical Examinations'!H:H, "No Data")} -> yes | J14: {=_xlfn.XLOOKUP($A14, 'Medical Examinations'!$A:$A, 'Medical Examinations'!I:I, "No Data")} -> Obesity | K14: {=_xlfn.XLOOKUP($A14, 'Hospitalisation Details'!$A:$A, 'Hospitalisation Details'!I:I, "No Data")} -> tier - 2 | L14: {=_xlfn.XLOOKUP($A14, 'Hospitalisation Details'!$A:$A, 'Hospitalisation Details'!J:J, "No Data")} -> R1013 | M14: {=_xlfn.XLOOKUP($A14, 'Hospitalisation Details'!$A:$A, 'Hospitalisation Details'!E:E, "No Data")} -> 11/10/62 | N14: {=_xlfn.XLOOKUP($A14, 'Hospitalisation Details'!$A:$A, 'Hospitalisation Details'!K:K, "No Data")} -> 60 | O14: {=_xlfn.XLOOKUP($A14, 'Hospitalisation Details'!$A:$A, 'Hospitalisation Details'!G:G, "No Data")} -> 48673.56 | P14: {=_xlfn.XLOOKUP($A14, 'Hospitalisation Details'!$A:$A, 'Hospitalisation Details'!H:H, "No Data")} -> tier - 1
A15: Id14 | B15: {=_xlfn.XLOOKUP($A15, 'Customer Names'!$A:$A, 'Customer Names'!B:B, "No Data")} -> Tenorio | C15: {=_xlfn.XLOOKUP($A15, 'Medical Examinations'!$A:$A, 'Medical Examinations'!B:B, "No Data")} -> 40.565 | D15: {=_xlfn.XLOOKUP($A15, 'Medical Examinations'!$A:$A, 'Medical Examinations'!C:C, "No Data")} -> 7.02 | E15: {=_xlfn.XLOOKUP($A15, 'Medical Examinations'!$A:$A, 'Medical Examinations'!D:D, "No Data")} -> No | F15: {=_xlfn.XLOOKUP($A15, 'Medical Examinations'!$A:$A, 'Medical Examinations'!E:E, "No Data")} -> No | G15: {=_xlfn.XLOOKUP($A15, 'Medical Examinations'!$A:$A, 'Medical Examinations'!F:F, "No Data")} -> No | H15: {=_xlfn.XLOOKUP($A15, 'Medical Examinations'!$A:$A, 'Medical Examinations'!G:G, "No Data")} -> 0 | I15: {=_xlfn.XLOOKUP($A15, 'Medical Examinations'!$A:$A, 'Medical Examinations'!H:H, "No Data")} -> yes | J15: {=_xlfn.XLOOKUP($A15, 'Medical Examinations'!$A:$A, 'Medical Examinations'!I:I, "No Data")} -> Obesity | K15: {=_xlfn.XLOOKUP($A15, 'Hospitalisation Details'!$A:$A, 'Hospitalisation Details'!I:I, "No Data")} -> tier - 3 | L15: {=_xlfn.XLOOKUP($A15, 'Hospitalisation Details'!$A:$A, 'Hospitalisation Details'!J:J, "No Data")} -> R1016 | M15: {=_xlfn.XLOOKUP($A15, 'Hospitalisation Details'!$A:$A, 'Hospitalisation Details'!E:E, "No Data")} -> 01/12/68 | N15: {=_xlfn.XLOOKUP($A15, 'Hospitalisation Details'!$A:$A, 'Hospitalisation Details'!K:K, "No Data")} -> 54 | O15: {=_xlfn.XLOOKUP($A15, 'Hospitalisation Details'!$A:$A, 'Hospitalisation Details'!G:G, "No Data")} -> 48549.18 | P15: {=_xlfn.XLOOKUP($A15, 'Hospitalisation Details'!$A:$A, 'Hospitalisation Details'!H:H, "No Data")} -> tier - 1
A16: Id15 | B16: {=_xlfn.XLOOKUP($A16, 'Customer Names'!$A:$A, 'Customer Names'!B:B, "No Data")} -> Rios | C16: {=_xlfn.XLOOKUP($A16, 'Medical Examinations'!$A:$A, 'Medical Examinations'!B:B, "No Data")} -> 36.385 | D16: {=_xlfn.XLOOKUP($A16, 'Medical Examinations'!$A:$A, 'Medical Examinations'!C:C, "No Data")} -> 7.59 | E16: {=_xlfn.XLOOKUP($A16, 'Medical Examinations'!$A:$A, 'Medical Examinations'!D:D, "No Data")} -> yes | F16: {=_xlfn.XLOOKUP($A16, 'Medical Examinations'!$A:$A, 'Medical Examinations'!E:E, "No Data")} -> No | G16: {=_xlfn.XLOOKUP($A16, 'Medical Examinations'!$A:$A, 'Medical Examinations'!F:F, "No Data")} -> No | H16: {=_xlfn.XLOOKUP($A16, 'Medical Examinations'!$A:$A, 'Medical Examinations'!G:G, "No Data")} -> 2 | I16: {=_xlfn.XLOOKUP($A16, 'Medical Examinations'!$A:$A, 'Medical Examinations'!H:H, "No Data")} -> yes | J16: {=_xlfn.XLOOKUP($A16, 'Medical Examinations'!$A:$A, 'Medical Examinations'!I:I, "No Data")} -> Obesity | K16: {=_xlfn.XLOOKUP($A16, 'Hospitalisation Details'!$A:$A, 'Hospitalisation Details'!I:I, "No Data")} -> tier - 3 | L16: {=_xlfn.XLOOKUP($A16, 'Hospitalisation Details'!$A:$A, 'Hospitalisation Details'!J:J, "No Data")} -> R1024 | M16: {=_xlfn.XLOOKUP($A16, 'Hospitalisation Details'!$A:$A, 'Hospitalisation Details'!E:E, "No Data")} -> 21/12/61 | N16: {=_xlfn.XLOOKUP($A16, 'Hospitalisation Details'!$A:$A, 'Hospitalisation Details'!K:K, "No Data")} -> 61 | O16: {=_xlfn.XLOOKUP($A16, 'Hospitalisation Details'!$A:$A, 'Hospitalisation Details'!G:G, "No Data")} -> 48517.56 | P16: {=_xlfn.XLOOKUP($A16, 'Hospitalisation Details'!$A:$A, 'Hospitalisation Details'!H:H, "No Data")} -> tier - 1
... A2318: Id2317 | B2318: {=_xlfn.XLOOKUP($A2318, 'Customer Names'!$A:$A, 'Customer Names'!B:B, "No Data")} -> Murakami | C2318: {=_xlfn.XLOOKUP($A2318, 'Medical Examinations'!$A:$A, 'Medical Examinations'!B:B, "No Data")} -> 20.47 | D2318: {=_xlfn.XLOOKUP($A2318, 'Medical Examinations'!$A:$A, 'Medical Examinations'!C:C, "No Data")} -> 5.81 | E2318: {=_xlfn.XLOOKUP($A2318, 'Medical Examinations'!$A:$A, 'Medical Examinations'!D:D, "No Data")} -> yes | F2318: {=_xlfn.XLOOKUP($A2318, 'Medical Examinations'!$A:$A, 'Medical Examinations'!E:E, "No Data")} -> No | G2318: {=_xlfn.XLOOKUP($A2318, 'Medical Examinations'!$A:$A, 'Medical Examinations'!F:F, "No Data")} -> No | H2318: {=_xlfn.XLOOKUP($A2318, 'Medical Examinations'!$A:$A, 'Medical Examinations'!G:G, "No Data")} -> 1 | I2318: {=_xlfn.XLOOKUP($A2318, 'Medical Examinations'!$A:$A, 'Medical Examinations'!H:H, "No Data")} -> No | J2318: {=_xlfn.XLOOKUP($A2318, 'Medical Examinations'!$A:$A, 'Medical Examinations'!I:I, "No Data")} -> Normal Weight | K2318: {=_xlfn.XLOOKUP($A2318, 'Hospitalisation Details'!$A:$A, 'Hospitalisation Details'!I:I, "No Data")} -> tier - 2 | L2318: {=_xlfn.XLOOKUP($A2318, 'Hospitalisation Details'!$A:$A, 'Hospitalisation Details'!J:J, "No Data")} -> R1013 | M2318: {=_xlfn.XLOOKUP($A2318, 'Hospitalisation Details'!$A:$A, 'Hospitalisation Details'!E:E, "No Data")} -> 07/12/95 | N2318: {=_xlfn.XLOOKUP($A2318, 'Hospitalisation Details'!$A:$A, 'Hospitalisation Details'!K:K, "No Data")} -> 27 | O2318: {=_xlfn.XLOOKUP($A2318, 'Hospitalisation Details'!$A:$A, 'Hospitalisation Details'!G:G, "No Data")} -> 773.54 | P2318: {=_xlfn.XLOOKUP($A2318, 'Hospitalisation Details'!$A:$A, 'Hospitalisation Details'!H:H, "No Data")} -> tier - 3
A2319: Id2318 | B2319: {=_xlfn.XLOOKUP($A2319, 'Customer Names'!$A:$A, 'Customer Names'!B:B, "No Data")} -> Gagnon | C2319: {=_xlfn.XLOOKUP($A2319, 'Medical Examinations'!$A:$A, 'Medical Examinations'!B:B, "No Data")} -> 18.82 | D2319: {=_xlfn.XLOOKUP($A2319, 'Medical Examinations'!$A:$A, 'Medical Examinations'!C:C, "No Data")} -> 5.51 | E2319: {=_xlfn.XLOOKUP($A2319, 'Medical Examinations'!$A:$A, 'Medical Examinations'!D:D, "No Data")} -> yes | F2319: {=_xlfn.XLOOKUP($A2319, 'Medical Examinations'!$A:$A, 'Medical Examinations'!E:E, "No Data")} -> No | G2319: {=_xlfn.XLOOKUP($A2319, 'Medical Examinations'!$A:$A, 'Medical Examinations'!F:F, "No Data")} -> No | H2319: {=_xlfn.XLOOKUP($A2319, 'Medical Examinations'!$A:$A, 'Medical Examinations'!G:G, "No Data")} -> 0 | I2319: {=_xlfn.XLOOKUP($A2319, 'Medical Examinations'!$A:$A, 'Medical Examinations'!H:H, "No Data")} -> No | J2319: {=_xlfn.XLOOKUP($A2319, 'Medical Examinations'!$A:$A, 'Medical Examinations'!I:I, "No Data")} -> Normal Weight | K2319: {=_xlfn.XLOOKUP($A2319, 'Hospitalisation Details'!$A:$A, 'Hospitalisation Details'!I:I, "No Data")} -> tier - 2 | L2319: {=_xlfn.XLOOKUP($A2319, 'Hospitalisation Details'!$A:$A, 'Hospitalisation Details'!J:J, "No Data")} -> R1012 | M2319: No Data | N2319: {=_xlfn.XLOOKUP($A2319, 'Hospitalisation Details'!$A:$A, 'Hospitalisation Details'!K:K, "No Data")} -> No Data | O2319: {=_xlfn.XLOOKUP($A2319, 'Hospitalisation Details'!$A:$A, 'Hospitalisation Details'!G:G, "No Data")} -> 770.38 | P2319: {=_xlfn.XLOOKUP($A2319, 'Hospitalisation Details'!$A:$A, 'Hospitalisation Details'!H:H, "No Data")} -> tier - 3
A2320: Id2319 | B2320: {=_xlfn.XLOOKUP($A2320, 'Customer Names'!$A:$A, 'Customer Names'!B:B, "No Data")} -> Petermann | C2320: {=_xlfn.XLOOKUP($A2320, 'Medical Examinations'!$A:$A, 'Medical Examinations'!B:B, "No Data")} -> 17.08 | D2320: {=_xlfn.XLOOKUP($A2320, 'Medical Examinations'!$A:$A, 'Medical Examinations'!C:C, "No Data")} -> 5.73 | E2320: {=_xlfn.XLOOKUP($A2320, 'Medical Examinations'!$A:$A, 'Medical Examinations'!D:D, "No Data")} -> No | F2320: {=_xlfn.XLOOKUP($A2320, 'Medical Examinations'!$A:$A, 'Medical Examinations'!E:E, "No Data")} -> No | G2320: {=_xlfn.XLOOKUP($A2320, 'Medical Examinations'!$A:$A, 'Medical Examinations'!F:F, "No Data")} -> Yes | H2320: {=_xlfn.XLOOKUP($A2320, 'Medical Examinations'!$A:$A, 'Medical Examinations'!G:G, "No Data")} -> 1 | I2320: {=_xlfn.XLOOKUP($A2320, 'Medical Examinations'!$A:$A, 'Medical Examinations'!H:H, "No Data")} -> No | J2320: {=_xlfn.XLOOKUP($A2320, 'Medical Examinations'!$A:$A, 'Medical Examinations'!I:I, "No Data")} -> Underweight | K2320: {=_xlfn.XLOOKUP($A2320, 'Hospitalisation Details'!$A:$A, 'Hospitalisation Details'!I:I, "No Data")} -> tier - 3 | L2320: {=_xlfn.XLOOKUP($A2320, 'Hospitalisation Details'!$A:$A, 'Hospitalisation Details'!J:J, "No Data")} -> R1013 | M2320: {=_xlfn.XLOOKUP($A2320, 'Hospitalisation Details'!$A:$A, 'Hospitalisation Details'!E:E, "No Data")} -> 28/06/93 | N2320: {=_xlfn.XLOOKUP($A2320, 'Hospitalisation Details'!$A:$A, 'Hospitalisation Details'!K:K, "No Data")} -> 29 | O2320: {=_xlfn.XLOOKUP($A2320, 'Hospitalisation Details'!$A:$A, 'Hospitalisation Details'!G:G, "No Data")} -> 770 | P2320: {=_xlfn.XLOOKUP($A2320, 'Hospitalisation Details'!$A:$A, 'Hospitalisation Details'!H:H, "No Data")} -> tier - 3
A2321: Id2320 | B2321: {=_xlfn.XLOOKUP($A2321, 'Customer Names'!$A:$A, 'Customer Names'!B:B, "No Data")} -> Graves - Rostro | C2321: {=_xlfn.XLOOKUP($A2321, 'Medical Examinations'!$A:$A, 'Medical Examinations'!B:B, "No Data")} -> 19.21 | D2321: {=_xlfn.XLOOKUP($A2321, 'Medical Examinations'!$A:$A, 'Medical Examinations'!C:C, "No Data")} -> 5.53 | E2321: {=_xlfn.XLOOKUP($A2321, 'Medical Examinations'!$A:$A, 'Medical Examinations'!D:D, "No Data")} -> yes | F2321: {=_xlfn.XLOOKUP($A2321, 'Medical Examinations'!$A:$A, 'Medical Examinations'!E:E, "No Data")} -> No | G2321: {=_xlfn.XLOOKUP($A2321, 'Medical Examinations'!$A:$A, 'Medical Examinations'!F:F, "No Data")} -> No | H2321: {=_xlfn.XLOOKUP($A2321, 'Medical Examinations'!$A:$A, 'Medical Examinations'!G:G, "No Data")} -> 0 | I2321: {=_xlfn.XLOOKUP($A2321, 'Medical Examinations'!$A:$A, 'Medical Examinations'!H:H, "No Data")} -> No | J2321: {=_xlfn.XLOOKUP($A2321, 'Medical Examinations'!$A:$A, 'Medical Examinations'!I:I, "No Data")} -> Normal Weight | K2321: {=_xlfn.XLOOKUP($A2321, 'Hospitalisation Details'!$A:$A, 'Hospitalisation Details'!I:I, "No Data")} -> tier - 3 | L2321: {=_xlfn.XLOOKUP($A2321, 'Hospitalisation Details'!$A:$A, 'Hospitalisation Details'!J:J, "No Data")} -> R1013 | M2321: {=_xlfn.XLOOKUP($A2321, 'Hospitalisation Details'!$A:$A, 'Hospitalisation Details'!E:E, "No Data")} -> 22/10/96 | N2321: {=_xlfn.XLOOKUP($A2321, 'Hospitalisation Details'!$A:$A, 'Hospitalisation Details'!K:K, "No Data")} -> 26 | O2321: {=_xlfn.XLOOKUP($A2321, 'Hospitalisation Details'!$A:$A, 'Hospitalisation Details'!G:G, "No Data")} -> 760 | P2321: {=_xlfn.XLOOKUP($A2321, 'Hospitalisation Details'!$A:$A, 'Hospitalisation Details'!H:H, "No Data")} -> tier - 3
A2322: Id2321 | B2322: {=_xlfn.XLOOKUP($A2322, 'Customer Names'!$A:$A, 'Customer Names'!B:B, "No Data")} -> Danielson | C2322: {=_xlfn.XLOOKUP($A2322, 'Medical Examinations'!$A:$A, 'Medical Examinations'!B:B, "No Data")} -> 17.86 | D2322: {=_xlfn.XLOOKUP($A2322, 'Medical Examinations'!$A:$A, 'Medical Examinations'!C:C, "No Data")} -> 5.43 | E2322: {=_xlfn.XLOOKUP($A2322, 'Medical Examinations'!$A:$A, 'Medical Examinations'!D:D, "No Data")} -> No | F2322: {=_xlfn.XLOOKUP($A2322, 'Medical Examinations'!$A:$A, 'Medical Examinations'!E:E, "No Data")} -> No | G2322: {=_xlfn.XLOOKUP($A2322, 'Medical Examinations'!$A:$A, 'Medical Examinations'!F:F, "No Data")} -> Yes | H2322: {=_xlfn.XLOOKUP($A2322, 'Medical Examinations'!$A:$A, 'Medical Examinations'!G:G, "No Data")} -> 1 | I2322: {=_xlfn.XLOOKUP($A2322, 'Medical Examinations'!$A:$A, 'Medical Examinations'!H:H, "No Data")} -> No | J2322: {=_xlfn.XLOOKUP($A2322, 'Medical Examinations'!$A:$A, 'Medical Examinations'!I:I, "No Data")} -> Underweight | K2322: {=_xlfn.XLOOKUP($A2322, 'Hospitalisation Details'!$A:$A, 'Hospitalisation Details'!I:I, "No Data")} -> tier - 1 | L2322: {=_xlfn.XLOOKUP($A2322, 'Hospitalisation Details'!$A:$A, 'Hospitalisation Details'!J:J, "No Data")} -> R1013 | M2322: {=_xlfn.XLOOKUP($A2322, 'Hospitalisation Details'!$A:$A, 'Hospitalisation Details'!E:E, "No Data")} -> 09/08/93 | N2322: {=_xlfn.XLOOKUP($A2322, 'Hospitalisation Details'!$A:$A, 'Hospitalisation Details'!K:K, "No Data")} -> 29 | O2322: {=_xlfn.XLOOKUP($A2322, 'Hospitalisation Details'!$A:$A, 'Hospitalisation Details'!G:G, "No Data")} -> 760 | P2322: {=_xlfn.XLOOKUP($A2322, 'Hospitalisation Details'!$A:$A, 'Hospitalisation Details'!H:H, "No Data")} -> tier - 3
A2323: Id2322 | B2323: {=_xlfn.XLOOKUP($A2323, 'Customer Names'!$A:$A, 'Customer Names'!B:B, "No Data")} -> Street | C2323: {=_xlfn.XLOOKUP($A2323, 'Medical Examinations'!$A:$A, 'Medical Examinations'!B:B, "No Data")} -> 21.38 | D2323: {=_xlfn.XLOOKUP($A2323, 'Medical Examinations'!$A:$A, 'Medical Examinations'!C:C, "No Data")} -> 8.01 | E2323: {=_xlfn.XLOOKUP($A2323, 'Medical Examinations'!$A:$A, 'Medical Examinations'!D:D, "No Data")} -> No | F2323: {=_xlfn.XLOOKUP($A2323, 'Medical Examinations'!$A:$A, 'Medical Examinations'!E:E, "No Data")} -> No | G2323: {=_xlfn.XLOOKUP($A2323, 'Medical Examinations'!$A:$A, 'Medical Examinations'!F:F, "No Data")} -> No | H2323: {=_xlfn.XLOOKUP($A2323, 'Medical Examinations'!$A:$A, 'Medical Examinations'!G:G, "No Data")} -> 0 | I2323: {=_xlfn.XLOOKUP($A2323, 'Medical Examinations'!$A:$A, 'Medical Examinations'!H:H, "No Data")} -> No | J2323: {=_xlfn.XLOOKUP($A2323, 'Medical Examinations'!$A:$A, 'Medical Examinations'!I:I, "No Data")} -> Normal Weight | K2323: {=_xlfn.XLOOKUP($A2323, 'Hospitalisation Details'!$A:$A, 'Hospitalisation Details'!I:I, "No Data")} -> tier - 1 | L2323: {=_xlfn.XLOOKUP($A2323, 'Hospitalisation Details'!$A:$A, 'Hospitalisation Details'!J:J, "No Data")} -> R1012 | M2323: No Data | N2323: {=_xlfn.XLOOKUP($A2323, 'Hospitalisation Details'!$A:$A, 'Hospitalisation Details'!K:K, "No Data")} -> No Data | O2323: {=_xlfn.XLOOKUP($A2323, 'Hospitalisation Details'!$A:$A, 'Hospitalisation Details'!G:G, "No Data")} -> 750 | P2323: {=_xlfn.XLOOKUP($A2323, 'Hospitalisation Details'!$A:$A, 'Hospitalisation Details'!H:H, "No Data")} -> tier - 3
A2324: Id2323 | B2324: {=_xlfn.XLOOKUP($A2324, 'Customer Names'!$A:$A, 'Customer Names'!B:B, "No Data")} -> Buss | C2324: {=_xlfn.XLOOKUP($A2324, 'Medical Examinations'!$A:$A, 'Medical Examinations'!B:B, "No Data")} -> 23.35 | D2324: {=_xlfn.XLOOKUP($A2324, 'Medical Examinations'!$A:$A, 'Medical Examinations'!C:C, "No Data")} -> 5.94 | E2324: {=_xlfn.XLOOKUP($A2324, 'Medical Examinations'!$A:$A, 'Medical Examinations'!D:D, "No Data")} -> No | F2324: {=_xlfn.XLOOKUP($A2324, 'Medical Examinations'!$A:$A, 'Medical Examinations'!E:E, "No Data")} -> No | G2324: {=_xlfn.XLOOKUP($A2324, 'Medical Examinations'!$A:$A, 'Medical Examinations'!F:F, "No Data")} -> No | H2324: {=_xlfn.XLOOKUP($A2324, 'Medical Examinations'!$A:$A, 'Medical Examinations'!G:G, "No Data")} -> 0 | I2324: {=_xlfn.XLOOKUP($A2324, 'Medical Examinations'!$A:$A, 'Medical Examinations'!H:H, "No Data")} -> No | J2324: {=_xlfn.XLOOKUP($A2324, 'Medical Examinations'!$A:$A, 'Medical Examinations'!I:I, "No Data")} -> Normal Weight | K2324: {=_xlfn.XLOOKUP($A2324, 'Hospitalisation Details'!$A:$A, 'Hospitalisation Details'!I:I, "No Data")} -> tier - 1 | L2324: {=_xlfn.XLOOKUP($A2324, 'Hospitalisation Details'!$A:$A, 'Hospitalisation Details'!J:J, "No Data")} -> R1013 | M2324: {=_xlfn.XLOOKUP($A2324, 'Hospitalisation Details'!$A:$A, 'Hospitalisation Details'!E:E, "No Data")} -> 14/12/99 | N2324: {=_xlfn.XLOOKUP($A2324, 'Hospitalisation Details'!$A:$A, 'Hospitalisation Details'!K:K, "No Data")} -> 23 | O2324: {=_xlfn.XLOOKUP($A2324, 'Hospitalisation Details'!$A:$A, 'Hospitalisation Details'!G:G, "No Data")} -> 722.99 | P2324: {=_xlfn.XLOOKUP($A2324, 'Hospitalisation Details'!$A:$A, 'Hospitalisation Details'!H:H, "No Data")} -> tier - 3
A2325: Id2324 | B2325: {=_xlfn.XLOOKUP($A2325, 'Customer Names'!$A:$A, 'Customer Names'!B:B, "No Data")} -> Duffy | C2325: {=_xlfn.XLOOKUP($A2325, 'Medical Examinations'!$A:$A, 'Medical Examinations'!B:B, "No Data")} -> 22.24 | D2325: {=_xlfn.XLOOKUP($A2325, 'Medical Examinations'!$A:$A, 'Medical Examinations'!C:C, "No Data")} -> 5.04 | E2325: {=_xlfn.XLOOKUP($A2325, 'Medical Examinations'!$A:$A, 'Medical Examinations'!D:D, "No Data")} -> No | F2325: {=_xlfn.XLOOKUP($A2325, 'Medical Examinations'!$A:$A, 'Medical Examinations'!E:E, "No Data")} -> No | G2325: {=_xlfn.XLOOKUP($A2325, 'Medical Examinations'!$A:$A, 'Medical Examinations'!F:F, "No Data")} -> No | H2325: {=_xlfn.XLOOKUP($A2325, 'Medical Examinations'!$A:$A, 'Medical Examinations'!G:G, "No Data")} -> 0 | I2325: {=_xlfn.XLOOKUP($A2325, 'Medical Examinations'!$A:$A, 'Medical Examinations'!H:H, "No Data")} -> No | J2325: {=_xlfn.XLOOKUP($A2325, 'Medical Examinations'!$A:$A, 'Medical Examinations'!I:I, "No Data")} -> Normal Weight | K2325: {=_xlfn.XLOOKUP($A2325, 'Hospitalisation Details'!$A:$A, 'Hospitalisation Details'!I:I, "No Data")} -> tier - 3 | L2325: {=_xlfn.XLOOKUP($A2325, 'Hospitalisation Details'!$A:$A, 'Hospitalisation Details'!J:J, "No Data")} -> R1013 | M2325: {=_xlfn.XLOOKUP($A2325, 'Hospitalisation Details'!$A:$A, 'Hospitalisation Details'!E:E, "No Data")} -> 26/12/99 | N2325: {=_xlfn.XLOOKUP($A2325, 'Hospitalisation Details'!$A:$A, 'Hospitalisation Details'!K:K, "No Data")} -> 23 | O2325: {=_xlfn.XLOOKUP($A2325, 'Hospitalisation Details'!$A:$A, 'Hospitalisation Details'!G:G, "No Data")} -> 700 | P2325: {=_xlfn.XLOOKUP($A2325, 'Hospitalisation Details'!$A:$A, 'Hospitalisation Details'!H:H, "No Data")} -> tier - 2
A2326: Id2325 | B2326: {=_xlfn.XLOOKUP($A2326, 'Customer Names'!$A:$A, 'Customer Names'!B:B, "No Data")} -> Hines | C2326: {=_xlfn.XLOOKUP($A2326, 'Medical Examinations'!$A:$A, 'Medical Examinations'!B:B, "No Data")} -> 24.76 | D2326: {=_xlfn.XLOOKUP($A2326, 'Medical Examinations'!$A:$A, 'Medical Examinations'!C:C, "No Data")} -> 4.54 | E2326: {=_xlfn.XLOOKUP($A2326, 'Medical Examinations'!$A:$A, 'Medical Examinations'!D:D, "No Data")} -> yes | F2326: {=_xlfn.XLOOKUP($A2326, 'Medical Examinations'!$A:$A, 'Medical Examinations'!E:E, "No Data")} -> No | G2326: {=_xlfn.XLOOKUP($A2326, 'Medical Examinations'!$A:$A, 'Medical Examinations'!F:F, "No Data")} -> No | H2326: {=_xlfn.XLOOKUP($A2326, 'Medical Examinations'!$A:$A, 'Medical Examinations'!G:G, "No Data")} -> 0 | I2326: {=_xlfn.XLOOKUP($A2326, 'Medical Examinations'!$A:$A, 'Medical Examinations'!H:H, "No Data")} -> No | J2326: {=_xlfn.XLOOKUP($A2326, 'Medical Examinations'!$A:$A, 'Medical Examinations'!I:I, "No Data")} -> Normal Weight | K2326: {=_xlfn.XLOOKUP($A2326, 'Hospitalisation Details'!$A:$A, 'Hospitalisation Details'!I:I, "No Data")} -> tier - 2 | L2326: {=_xlfn.XLOOKUP($A2326, 'Hospitalisation Details'!$A:$A, 'Hospitalisation Details'!J:J, "No Data")} -> R1013 | M2326: {=_xlfn.XLOOKUP($A2326, 'Hospitalisation Details'!$A:$A, 'Hospitalisation Details'!E:E, "No Data")} -> 12/09/01 | N2326: {=_xlfn.XLOOKUP($A2326, 'Hospitalisation Details'!$A:$A, 'Hospitalisation Details'!K:K, "No Data")} -> 21 | O2326: {=_xlfn.XLOOKUP($A2326, 'Hospitalisation Details'!$A:$A, 'Hospitalisation Details'!G:G, "No Data")} -> 687.54 | P2326: {=_xlfn.XLOOKUP($A2326, 'Hospitalisation Details'!$A:$A, 'Hospitalisation Details'!H:H, "No Data")} -> tier - 3
A2327: Id2326 | B2327: {=_xlfn.XLOOKUP($A2327, 'Customer Names'!$A:$A, 'Customer Names'!B:B, "No Data")} -> Castro | C2327: {=_xlfn.XLOOKUP($A2327, 'Medical Examinations'!$A:$A, 'Medical Examinations'!B:B, "No Data")} -> 20.1 | D2327: {=_xlfn.XLOOKUP($A2327, 'Medical Examinations'!$A:$A, 'Medical Examinations'!C:C, "No Data")} -> 5.6 | E2327: {=_xlfn.XLOOKUP($A2327, 'Medical Examinations'!$A:$A, 'Medical Examinations'!D:D, "No Data")} -> yes | F2327: {=_xlfn.XLOOKUP($A2327, 'Medical Examinations'!$A:$A, 'Medical Examinations'!E:E, "No Data")} -> No | G2327: {=_xlfn.XLOOKUP($A2327, 'Medical Examinations'!$A:$A, 'Medical Examinations'!F:F, "No Data")} -> Yes | H2327: {=_xlfn.XLOOKUP($A2327, 'Medical Examinations'!$A:$A, 'Medical Examinations'!G:G, "No Data")} -> 1 | I2327: {=_xlfn.XLOOKUP($A2327, 'Medical Examinations'!$A:$A, 'Medical Examinations'!H:H, "No Data")} -> No | J2327: {=_xlfn.XLOOKUP($A2327, 'Medical Examinations'!$A:$A, 'Medical Examinations'!I:I, "No Data")} -> Normal Weight | K2327: {=_xlfn.XLOOKUP($A2327, 'Hospitalisation Details'!$A:$A, 'Hospitalisation Details'!I:I, "No Data")} -> tier - 3 | L2327: {=_xlfn.XLOOKUP($A2327, 'Hospitalisation Details'!$A:$A, 'Hospitalisation Details'!J:J, "No Data")} -> R1013 | M2327: {=_xlfn.XLOOKUP($A2327, 'Hospitalisation Details'!$A:$A, 'Hospitalisation Details'!E:E, "No Data")} -> 09/11/97 | N2327: {=_xlfn.XLOOKUP($A2327, 'Hospitalisation Details'!$A:$A, 'Hospitalisation Details'!K:K, "No Data")} -> 25 | O2327: {=_xlfn.XLOOKUP($A2327, 'Hospitalisation Details'!$A:$A, 'Hospitalisation Details'!G:G, "No Data")} -> 670 | P2327: {=_xlfn.XLOOKUP($A2327, 'Hospitalisation Details'!$A:$A, 'Hospitalisation Details'!H:H, "No Data")} -> tier - 3
A2328: Id2327 | B2328: {=_xlfn.XLOOKUP($A2328, 'Customer Names'!$A:$A, 'Customer Names'!B:B, "No Data")} -> Howell | C2328: {=_xlfn.XLOOKUP($A2328, 'Medical Examinations'!$A:$A, 'Medical Examinations'!B:B, "No Data")} -> 21.77 | D2328: {=_xlfn.XLOOKUP($A2328, 'Medical Examinations'!$A:$A, 'Medical Examinations'!C:C, "No Data")} -> 10.67 | E2328: {=_xlfn.XLOOKUP($A2328, 'Medical Examinations'!$A:$A, 'Medical Examinations'!D:D, "No Data")} -> No | F2328: {=_xlfn.XLOOKUP($A2328, 'Medical Examinations'!$A:$A, 'Medical Examinations'!E:E, "No Data")} -> No | G2328: {=_xlfn.XLOOKUP($A2328, 'Medical Examinations'!$A:$A, 'Medical Examinations'!F:F, "No Data")} -> No | H2328: {=_xlfn.XLOOKUP($A2328, 'Medical Examinations'!$A:$A, 'Medical Examinations'!G:G, "No Data")} -> 0 | I2328: {=_xlfn.XLOOKUP($A2328, 'Medical Examinations'!$A:$A, 'Medical Examinations'!H:H, "No Data")} -> No | J2328: {=_xlfn.XLOOKUP($A2328, 'Medical Examinations'!$A:$A, 'Medical Examinations'!I:I, "No Data")} -> Normal Weight | K2328: {=_xlfn.XLOOKUP($A2328, 'Hospitalisation Details'!$A:$A, 'Hospitalisation Details'!I:I, "No Data")} -> tier - 2 | L2328: {=_xlfn.XLOOKUP($A2328, 'Hospitalisation Details'!$A:$A, 'Hospitalisation Details'!J:J, "No Data")} -> R1012 | M2328: {=_xlfn.XLOOKUP($A2328, 'Hospitalisation Details'!$A:$A, 'Hospitalisation Details'!E:E, "No Data")} -> 29/11/02 | N2328: {=_xlfn.XLOOKUP($A2328, 'Hospitalisation Details'!$A:$A, 'Hospitalisation Details'!K:K, "No Data")} -> 20 | O2328: {=_xlfn.XLOOKUP($A2328, 'Hospitalisation Details'!$A:$A, 'Hospitalisation Details'!G:G, "No Data")} -> 668 | P2328: {=_xlfn.XLOOKUP($A2328, 'Hospitalisation Details'!$A:$A, 'Hospitalisation Details'!H:H, "No Data")} -> tier - 3
